import 'dart:convert';
import 'package:flutter/widgets.dart';
import 'package:http/http.dart' as http;

import '../models/http_exception.dart';

class Auth with ChangeNotifier {
  String _token;
  DateTime _expiryDate;
  String _userId;

  bool get isAuth {
    return token != null;
  }

  String get token {
    if (_expiryDate != null &&
        _expiryDate.isAfter(DateTime.now()) &&
        _token != null) {
      return _token;
    }
    return null;
  }

  Future<void> _authenticate(
      String email, String password, String urlSegment) async {
    var url =
        'https://identitytoolkit.googleapis.com/v1/accounts:$urlSegment?key=AIzaSyDHeLOJRXJ5I_xuChJI3zePoDbFhGQDuhs';
    try {
      final response = await http.post(
        Uri.parse(url),
        body: json.encode(
          {
            'email': email,
            'password': password,
            'returnSecureToken': true,
          },
        ),
      );
      final responseData = json.decode(response.body);
      ////why trying to catch error here also? cuz if firebase base return a response,
      ////it will be 2xx response, even if it contain a an error code 400,
      ////.. it will contain it as text not as a real error code
      if (responseData['error'] != null) {
        throw HttpException(responseData['error']['message']);
      }
      _token = responseData['idToken'];
      _userId = responseData['localId'];
      _expiryDate = DateTime.now().add(
        Duration(
          seconds: int.parse(
            responseData['expiresIn'],
          ),
        ),
      );
      notifyListeners();
    } catch (error) {
      ////.. but this one is a real 400 code!!!
      ////.. like a network error and so on
      throw error;
    }
  }

  Future<void> signup(String email, String password) async {
    return _authenticate(email, password, 'signUp');
  }

  Future<void> login(String email, String password) async {
    return _authenticate(email, password, 'signInWithPassword');
  }
}
